[2023-09-04 12:17:44,771]241django.request-ERROR-Internal Server Error: /ask/
concurrent.futures.process._RemoteTraceback: 
"""
Traceback (most recent call last):
  File "C:\Users\parth.chaturvedi\Desktop\django\myworld\Lib\site-packages\langchain\document_loaders\pdf.py", line 235, in __init__
    from pdfminer.high_level import extract_text  # noqa:F401
    ^^^^^^^^^^^^^^^^^^^^^^^^^^^^^^^^^^^^^^^^^^^^
ModuleNotFoundError: No module named 'pdfminer'

During handling of the above exception, another exception occurred:

Traceback (most recent call last):
  File "C:\Program Files\Python311\Lib\concurrent\futures\process.py", line 256, in _process_worker
    r = call_item.fn(*call_item.args, **call_item.kwargs)
        ^^^^^^^^^^^^^^^^^^^^^^^^^^^^^^^^^^^^^^^^^^^^^^^^^
  File "C:\Users\parth.chaturvedi\Desktop\django\my_tennis_club\members\ingest.py", line 45, in load_document_batch
    data_list = [future.result() for future in futures]
                ^^^^^^^^^^^^^^^^^^^^^^^^^^^^^^^^^^^^^^^
  File "C:\Users\parth.chaturvedi\Desktop\django\my_tennis_club\members\ingest.py", line 45, in <listcomp>
    data_list = [future.result() for future in futures]
                 ^^^^^^^^^^^^^^^
  File "C:\Program Files\Python311\Lib\concurrent\futures\_base.py", line 456, in result
    return self.__get_result()
           ^^^^^^^^^^^^^^^^^^^
  File "C:\Program Files\Python311\Lib\concurrent\futures\_base.py", line 401, in __get_result
    raise self._exception
  File "C:\Program Files\Python311\Lib\concurrent\futures\thread.py", line 58, in run
    result = self.fn(*self.args, **self.kwargs)
             ^^^^^^^^^^^^^^^^^^^^^^^^^^^^^^^^^^
  File "C:\Users\parth.chaturvedi\Desktop\django\my_tennis_club\members\ingest.py", line 32, in load_single_document
    loader = loader_class(file_path)
             ^^^^^^^^^^^^^^^^^^^^^^^
  File "C:\Users\parth.chaturvedi\Desktop\django\myworld\Lib\site-packages\langchain\document_loaders\pdf.py", line 237, in __init__
    raise ImportError(
ImportError: `pdfminer` package not found, please install it with `pip install pdfminer.six`
"""

The above exception was the direct cause of the following exception:

Traceback (most recent call last):
  File "C:\Users\parth.chaturvedi\Desktop\django\myworld\Lib\site-packages\django\core\handlers\exception.py", line 55, in inner
    response = get_response(request)
               ^^^^^^^^^^^^^^^^^^^^^
  File "C:\Users\parth.chaturvedi\Desktop\django\myworld\Lib\site-packages\django\core\handlers\base.py", line 197, in _get_response
    response = wrapped_callback(request, *callback_args, **callback_kwargs)
               ^^^^^^^^^^^^^^^^^^^^^^^^^^^^^^^^^^^^^^^^^^^^^^^^^^^^^^^^^^^^
  File "C:\Users\parth.chaturvedi\Desktop\django\myworld\Lib\site-packages\django\views\decorators\csrf.py", line 56, in wrapper_view
    return view_func(*args, **kwargs)
           ^^^^^^^^^^^^^^^^^^^^^^^^^^
  File "C:\Users\parth.chaturvedi\Desktop\django\my_tennis_club\members\views.py", line 63, in ask_question
    documents = load_documents(SOURCE_DIRECTORY)
                ^^^^^^^^^^^^^^^^^^^^^^^^^^^^^^^^
  File "C:\Users\parth.chaturvedi\Desktop\django\my_tennis_club\members\ingest.py", line 76, in load_documents
    contents, _ = future.result()
                  ^^^^^^^^^^^^^^^
  File "C:\Program Files\Python311\Lib\concurrent\futures\_base.py", line 449, in result
    return self.__get_result()
           ^^^^^^^^^^^^^^^^^^^
  File "C:\Program Files\Python311\Lib\concurrent\futures\_base.py", line 401, in __get_result
    raise self._exception
ImportError: `pdfminer` package not found, please install it with `pip install pdfminer.six`
