[2023-09-04 12:08:07,682]241django.request-ERROR-Internal Server Error: /upload/
Traceback (most recent call last):
  File "C:\Users\parth.chaturvedi\Desktop\django\myworld\Lib\site-packages\django\core\handlers\exception.py", line 55, in inner
    response = get_response(request)
               ^^^^^^^^^^^^^^^^^^^^^
  File "C:\Users\parth.chaturvedi\Desktop\django\myworld\Lib\site-packages\django\core\handlers\base.py", line 197, in _get_response
    response = wrapped_callback(request, *callback_args, **callback_kwargs)
               ^^^^^^^^^^^^^^^^^^^^^^^^^^^^^^^^^^^^^^^^^^^^^^^^^^^^^^^^^^^^
  File "C:\Users\parth.chaturvedi\Desktop\django\myworld\Lib\site-packages\django\views\decorators\csrf.py", line 56, in wrapper_view
    return view_func(*args, **kwargs)
           ^^^^^^^^^^^^^^^^^^^^^^^^^^
  File "C:\Users\parth.chaturvedi\Desktop\django\my_tennis_club\members\views.py", line 52, in upload_file
    file.save(file_path)
    ^^^^^^^^^
AttributeError: 'InMemoryUploadedFile' object has no attribute 'save'
